<?xml version='1.0'?>
<sdf version ='1.6'>

  <model name ='sliding_door'>
   <pose>0 0 0 0 0 0</pose>

   <link name ='rail_link'>
     <pose>0 0.5 0 0 0 0</pose>
     <inertial>
      <mass>2</mass>
     </inertial>
     <collision name ='rail_collision'>
     <geometry>
        <box><size>0.08 2.0 0.001</size></box>
      </geometry>
     </collision>
     <visual name ='rail_visual'>
       <geometry>
         <box><size>0.08 2.0 0.001</size></box>
       </geometry>
     </visual>
   </link>

   <link name ='door_link'>
     <pose>0 0 1.11 0 0 0</pose>
     <inertial>
       <mass>3</mass>
     </inertial>
     <collision name ='door_collision'>
       <geometry>
         <box><size>0.08 1.0 2.20</size></box>
       </geometry>
     </collision>
     <visual name ='door_visual'>
       <geometry>
         <box><size>0.08 1.0 2.20</size></box>
       </geometry>
     </visual>
   </link>

   <!-- <link name ='region_link'>
     <pose>0 0 1.11 0 0 0</pose>
     <visual name ='region_visual'>
       <geometry>
         <box><size>2.0 1.0 2.20</size></box>
       </geometry>
       <transparency>0.9</transparency>
     </visual>
    </link> -->

   <joint name='door_joint' type='prismatic'>
     <parent>rail_link</parent>
     <child>door_link</child>
     <axis>
       <xyz>0 1 0</xyz>
       <limit>
         <lower>0</lower>
         <upper>1</upper>
         <effort>10</effort>
       </limit>
       <dynamics>
         <damping>2</damping>
       </dynamics>
     </axis>
   </joint>

   <!-- <joint name='region_joint' type='fixed'>
     <parent>rail_link</parent>
     <child>region_link</child>
   </joint> -->

  </model>

</sdf>
